Workbook

Sheet Обложка
B2: Мандат — финансовая модель
B3: Версия 1.0 от 27.10.2026. Трек ВТБ «Финтех без границ», «Академия Финтеха 2026». Деньги — млн ₽ без НДС; цены 2027 года, дальше индексация
B5: Главное
B6: Показатель | C6: Консервативный | D6: Базовый | E6: Оптимистичный
B7: Высвобождается ставок в ВТБ | C7: =Сводка!D6 -> 33 | D7: =Сводка!E6 -> 75 | E7: =Сводка!F6 -> 167
B8: Предотвращённый ущерб клиентов ВТБ, млн ₽ в год | C8: =Сводка!D7 -> 34 | D8: =Сводка!E7 -> 115 | E8: =Сводка!F7 -> 229
B9: Окупаемость для ВТБ (деньги), месяцев | C9: =Сводка!D11 -> 33.074022 | D9: =Сводка!E11 -> 8.0099861 | E9: =Сводка!F11 -> 1.5072704
B10: SAM: банки уровней 1 и 2, одна операция, млн ₽ в год | C10: =Сводка!D15 -> 101.1 | D10: =Сводка!E15 -> 186.75 | E10: =Сводка!F15 -> 251.85
B11: Выручка 2031 года, млн ₽ | C11: =Сводка!D21 -> 11.947181 | D11: =Сводка!E21 -> 67.776952 | E11: =Сводка!F21 -> 141.84839
B12: Потребность в финансировании, млн ₽ | C12: =Сводка!D26 -> 78.123714 | D12: =Сводка!E26 -> 33.332275 | E12: =Сводка!F26 -> 39.390185
B13: Год выхода на операционную прибыль | C13: =Сводка!D27 -> после 2031 | D13: =Сводка!E27 -> 2029 | E13: =Сводка!F27 -> 2030
B14: NPV с остаточной стоимостью, млн ₽ | C14: =Сводка!D30 -> -31.664046 | D14: =Сводка!E30 -> -0.14959473 | E14: =Сводка!F30 -> 41.570143
B16: Статус проверок | C16: =Проверки!$F$50 -> ОК | D16: ="Ошибок: "&Проверки!$E$48&", предупреждений: "&Проверки!$E$49 -> Ошибок: 0, предупреждений: 0
B18: Что внутри
B19: Сводка | C19: главные результаты трёх сценариев и графики
B20: Допущения | C20: все параметры по сценариям с типом, источником и способом проверки на пилоте
B21: План | C21: договоры с банками и команда по годам
B22: Эффект для банка | C22: ставки и ущерб как в презентации, деньги для ВТБ, окупаемость, «купить или сделать»
B23: Рынок | C23: TAM, SAM, SOM снизу вверх и сверху вниз
B24: Консервативный, Базовый, Оптимистичный | C24: полный расчёт сценария: выручка, затраты, отчёт, деньги, NPV
B25: Чувствительность | C25: NPV базового сценария при ±20 % по каждому допущению
B26: Проверки | C26: целостность модели и рамки допущений
B27: Источники | C27: откуда взяты факты
B29: Как пользоваться
B30: • Меняйте только синие ячейки на листах «Допущения» и «План»: каждый сценарий — свой столбец. Всё остальное — формулы.
B31: • Жёлтая заливка — допущения, которые банк заменит своими данными на пилоте (клиенты, события, минуты, оклады, цена).
B32: • Зелёный — ссылка на другой лист, чёрный — формула на этом листе.
B33: • После правки посмотрите лист «Проверки»: итог должен быть «ОК».
B34: • Пересобрать с нуля: python submission/analytics/build_model.py (нужен LibreOffice для пересчёта).
B36: Легенда
C37: 12,3 | D37: введено руками (допущение)
C38: 12,3 | D38: ключевое допущение
C39: 12,3 | D39: ссылка на другой лист
C40: 12,3 | D40: формула

Sheet Сводка
A1: Сводка по сценариям
A2: Все числа — ссылки на листы сценариев; млн ₽ без НДС
A4: № | B4: Показатель | C4: Единица | D4: Консервативный | E4: Базовый | F4: Оптимистичный
A5: Эффект для ВТБ
A6: 1 | B6: Высвобождается ставок | C6: ставок | D6: ='Эффект для банка'!$D$36 -> 33 | E6: ='Эффект для банка'!$E$36 -> 75 | F6: ='Эффект для банка'!$F$36 -> 167
A7: 2 | B7: Предотвращённый ущерб клиентов | C7: млн ₽ в год | D7: ='Эффект для банка'!$D$44 -> 34 | E7: ='Эффект для банка'!$E$44 -> 115 | F7: ='Эффект для банка'!$F$44 -> 229
A8: 3 | B8: Прямой эффект банка: ёмкость | C8: млн ₽ в год | D8: ='Эффект для банка'!$D$47 -> 56.5596 | E8: ='Эффект для банка'!$E$47 -> 164.6964 | F8: ='Эффект для банка'!$F$47 -> 463.524
A9: 4 | B9: Прямой эффект банка: деньги | C9: млн ₽ в год | D9: ='Эффект для банка'!$D$48 -> 19.37448 | E9: ='Эффект для банка'!$E$48 -> 91.4589 | F9: ='Эффект для банка'!$F$48 -> 341.6568
A10: 5 | B10: Подписка для ВТБ (цены 2027) | C10: млн ₽ в год | D10: ='Эффект для банка'!$D$51 -> 6.6 | E10: ='Эффект для банка'!$E$51 -> 15 | F10: ='Эффект для банка'!$F$51 -> 20.6
A11: 6 | B11: Окупаемость для ВТБ: деньги | C11: месяцев | D11: ='Эффект для банка'!$D$60 -> 33.074022 | E11: ='Эффект для банка'!$E$60 -> 8.0099861 | F11: ='Эффект для банка'!$F$60 -> 1.5072704
A12: 7 | B12: Отдача за 3 года на вложенный рубль: деньги | C12: раз | D12: ='Эффект для банка'!$D$59 -> 0.055945062 | E12: ='Эффект для банка'!$E$59 -> 2.2313065 | F12: ='Эффект для банка'!$F$59 -> 9.1022117
A13: Рынок
A14: 8 | B14: TAM: все банки России | C14: млн ₽ в год | D14: =Рынок!$D$36 -> 173.4 | E14: =Рынок!$E$36 -> 307.25 | F14: =Рынок!$F$36 -> 420.55
A15: 9 | B15: SAM: банки уровней 1 и 2, одна операция | C15: млн ₽ в год | D15: =Рынок!$D$37 -> 101.1 | E15: =Рынок!$E$37 -> 186.75 | F15: =Рынок!$F$37 -> 251.85
A16: 10 | B16: SAM при полном охвате операций | C16: млн ₽ в год | D16: =Рынок!$D$40 -> 101.1 | E16: =Рынок!$E$40 -> 326.62692 | F16: =Рынок!$F$40 -> 614.86816
A17: 11 | B17: SOM: подписка на конец 2031 (цены 2027) | C17: млн ₽ в год | D17: =Рынок!$D$44 -> 9.76875 | E17: =Рынок!$E$44 -> 61.400727 | F17: =Рынок!$F$44 -> 134.74225
A18: 12 | B18: SOM в доле SAM при полном охвате | C18: доля | D18: =Рынок!$D$45 -> 0.096624629 | E18: =Рынок!$E$45 -> 0.18798428 | F18: =Рынок!$F$45 -> 0.21914007
A19: Проект
A20: 13 | B20: Выручка 2027–2031 | C20: млн ₽ | D20: =Консервативный!$D$126 -> 37.247677 | E20: =Базовый!$D$126 -> 171.04852 | F20: =Оптимистичный!$D$126 -> 322.68477
A21: 14 | B21: Выручка 2031 | C21: млн ₽ | D21: =Консервативный!$D$127 -> 11.947181 | E21: =Базовый!$D$127 -> 67.776952 | F21: =Оптимистичный!$D$127 -> 141.84839
A22: 15 | B22: ARR на конец 2031 | C22: млн ₽ | D22: =Консервативный!$D$128 -> 11.428056 | E22: =Базовый!$D$128 -> 74.632967 | F22: =Оптимистичный!$D$128 -> 170.10899
A23: 16 | B23: Операционная прибыль 2031 | C23: млн ₽ | D23: =Консервативный!$D$129 -> -11.838856 | E23: =Базовый!$D$129 -> 20.079808 | F23: =Оптимистичный!$D$129 -> 53.050325
A24: 17 | B24: Банков с договором к концу 2031 | C24: банков | D24: =Консервативный!$D$130 -> 4 | E24: =Базовый!$D$130 -> 11 | F24: =Оптимистичный!$D$130 -> 18
A25: 18 | B25: Команда к концу 2031 | C25: ставок | D25: =Консервативный!$D$131 -> 4 | E25: =Базовый!$D$131 -> 8 | F25: =Оптимистичный!$D$131 -> 15
A26: 19 | B26: Потребность в финансировании с запасом | C26: млн ₽ | D26: =Консервативный!$D$133 -> 78.123714 | E26: =Базовый!$D$133 -> 33.332275 | F26: =Оптимистичный!$D$133 -> 39.390185
A27: 20 | B27: Год выхода на операционную прибыль | C27: год | D27: =Консервативный!$D$138 -> после 2031 | E27: =Базовый!$D$138 -> 2029 | F27: =Оптимистичный!$D$138 -> 2030
A28: 21 | B28: Год окупаемости вложений | C28: год | D28: =Консервативный!$D$139 -> после 2031 | E28: =Базовый!$D$139 -> после 2031 | F28: =Оптимистичный!$D$139 -> 2031
A29: 22 | B29: NPV без остаточной стоимости | C29: млн ₽ | D29: =Консервативный!$D$135 -> -31.664046 | E29: =Базовый!$D$135 -> -14.756216 | F29: =Оптимистичный!$D$135 -> -4.248058
A30: 23 | B30: NPV с остаточной стоимостью | C30: млн ₽ | D30: =Консервативный!$D$136 -> -31.664046 | E30: =Базовый!$D$136 -> -0.14959473 | F30: =Оптимистичный!$D$136 -> 41.570143
A31: 24 | B31: IRR с остаточной стоимостью | C31: доля | D31: =Консервативный!$D$137 -> н/д | E31: =Базовый!$D$137 -> 0.29711998 | F31: =Оптимистичный!$D$137 -> 0.78510393
A33: № | B33: Показатель по годам | C33: Сценарий | D33: 2027 | E33: 2028 | F33: 2029 | G33: 2030 | H33: 2031
B34: Выручка | C34: Консервативный | D34: =Консервативный!F74 -> 0 | E34: =Консервативный!G74 -> 6.24 | F34: =Консервативный!H74 -> 8.76096 | G34: =Консервативный!I74 -> 10.299536 | H34: =Консервативный!J74 -> 11.947181
B35: Выручка | C35: Базовый | D35: =Базовый!F74 -> 8 | E35: =Базовый!G74 -> 17.85 | F35: =Базовый!H74 -> 34.056914 | G35: =Базовый!I74 -> 43.364649 | H35: =Базовый!J74 -> 67.776952
B36: Выручка | C36: Оптимистичный | D36: =Оптимистичный!F74 -> 10 | E36: =Оптимистичный!G74 -> 27.136 | F36: =Оптимистичный!H74 -> 53.532517 | G36: =Оптимистичный!I74 -> 90.167863 | H36: =Оптимистичный!J74 -> 141.84839
B37: Операционная прибыль | C37: Консервативный | D37: =Консервативный!F105 -> -11.048796 | E37: =Консервативный!G105 -> -13.904266 | F37: =Консервативный!H105 -> -12.353668 | G37: =Консервативный!I105 -> -12.029669 | H37: =Консервативный!J105 -> -11.838856
B38: Операционная прибыль | C38: Базовый | D38: =Базовый!F105 -> -14.07621 | E38: =Базовый!G105 -> -7.10975 | F38: =Базовый!H105 -> 1.8529838 | G38: =Базовый!I105 -> 4.0472884 | H38: =Базовый!J105 -> 20.079808
B39: Операционная прибыль | C39: Оптимистичный | D39: =Оптимистичный!F105 -> -13.50621 | E39: =Оптимистичный!G105 -> -9.8447412 | F39: =Оптимистичный!H105 -> -0.67433728 | G39: =Оптимистичный!I105 -> 22.948053 | H39: =Оптимистичный!J105 -> 53.050325
B40: Накопленный денежный поток | C40: Консервативный | D40: =Консервативный!F117 -> -11.048796 | E40: =Консервативный!G117 -> -27.004569 | F40: =Консервативный!H117 -> -40.187046 | G40: =Консервативный!I117 -> -52.722548 | H40: =Консервативный!J117 -> -65.103095
B41: Накопленный денежный поток | C41: Базовый | D41: =Базовый!F117 -> -16.048813 | E41: =Базовый!G117 -> -25.58733 | F41: =Базовый!H117 -> -27.776896 | G41: =Базовый!I117 -> -26.125848 | H41: =Базовый!J117 -> -12.567507
B42: Накопленный денежный поток | C42: Оптимистичный | D42: =Оптимистичный!F117 -> -15.150045 | E42: =Оптимистичный!G117 -> -27.811663 | F42: =Оптимистичный!H117 -> -32.825154 | G42: =Оптимистичный!I117 -> -16.473051 | H42: =Оптимистичный!J117 -> 26.056892
...

Sheet Допущения
A1: Допущения
A2: Синий — введено руками, жёлтая заливка — ключевые допущения, которые банк заменит своими данными
A3: Год начала модели (исходные остатки) | D3: 2026
A5: № | B5: Параметр | C5: Единица | D5: Консервативный | E5: Базовый | F5: Оптимистичный | G5: Тип | H5: Источник или обоснование | I5: Как проверить на пилоте
A6: П. Эффект для ВТБ: параметры презентации (effect_scenarios.json)
A7: П1 | B7: Клиенты ВТБ — предприятия и предприниматели | C7: млн | D7: 1.8 | E7: 1.8 | F7: 1.8 | G7: вторичный | H7: Пресс-релиз ВТБ к МСФО за I полугодие 2026 в пересказе altapress.ru и kp.ru (M-09, S05) | I7: внутренняя цифра банка
A8: П2 | B8: Доля клиентов со сменой или добавлением подписанта в год | C8: доля | D8: 0.1 | E8: 0.15 | F8: 0.25 | G8: допущение | H8: Допущение команды (C-15); публичных данных нет | I8: число событий за год в журнале банка
A9: П3 | B9: Минут на кейс вручную, вместе с разбором | C9: минут | D9: 20 | E9: 30 | F9: 40 | G9: допущение | H9: Допущение команды (C-15); замер — в пилоте | I9: хронометраж в пилоте
A10: П4 | B10: Рабочих часов на ставку в год | C10: часов | D10: 1800 | E10: 1800 | F10: 1800 | G10: допущение | H10: Около 1 970 часов по производственному календарю минус отпуск | I10: норма банка
A11: П5 | B11: Операций без согласия у юрлиц за квартал | C11: операций | D11: 818 | E11: 818 | F11: 818 | G11: факт | H11: Банк России, I кв. 2026 (M-07, S03) | I11: —
A12: П6 | B12: Объём таких операций за квартал | C12: млн ₽ | D12: 573 | E12: 573 | F12: 573 | G12: факт | H12: Банк России, I кв. 2026 (M-07, S03) | I12: —
A13: П7 | B13: Доля ВТБ в таких инцидентах | C13: доля | D13: 0.15 | E13: 0.2 | F13: 0.25 | G13: допущение | H13: Допущение команды (C-16) | I13: данные антифрода банка
A14: П8 | B14: Доля инцидентов, связанных с полномочиями | C14: доля | D14: 0.1 | E14: 0.25 | F14: 0.4 | G14: допущение | H14: Допущение команды (C-16) | I14: разметка инцидентов банка
A15: Э. Эффект для ВТБ: стоимость времени и доля ущерба
A16: Э1 | B16: Оклад сотрудника, проверяющего документы | C16: тыс. ₽ в месяц | D16: 85 | E16: 100 | F16: 120 | G16: допущение | H16: Вакансии операционистов по работе с юрлицами — от 60–100 тыс. ₽ до вычета налогов (hh.ru, октябрь 2026, S14); средняя по финансовой отрасли — 314 тыс. ₽ (Росстат, март 2026, S13) — верхний ориентир | I16: фонд оплаты труда подразделения по данным банка
A17: Э2 | B17: Страховые взносы банка | C17: доля | D17: 0.302 | E17: 0.302 | F17: 0.302 | G17: факт | H17: Общий тариф 30 % в пределах базы и взнос на травматизм от 0,2 % (НК РФ, гл. 34; 125-ФЗ) | I17: тариф банка на травматизм
A18: Э3 | B18: Накладные на рабочее место (помещение, ИТ, управление) | C18: доля к ФОТ с взносами | D18: 0.2 | E18: 0.25 | F18: 0.3 | G18: допущение | H18: Оценка команды для бэк-офиса крупного банка | I18: методика внутреннего учёта затрат банка
A19: Э4 | B19: Доля высвобожденного времени, которая становится экономией | C19: доля | D19: 0.3 | E19: 0.5 | F19: 0.7 | G19: допущение | H19: Высвобожденное время становится деньгами, только если банк перераспределяет людей или не нанимает новых; остальное — ёмкость под рост потока | I19: план банка по численности подразделения
A20: Э5 | B20: Доля предотвращённого ущерба клиентов, которую несёт банк | C20: доля | D20: 0.1 | E20: 0.159 | F20: 0.25 | G20: допущение | H20: Ориентир — доля возмещённого юрлицам по счетам в I кв. 2026: 15,9 % (Банк России, M-07, S03) | I20: данные банка о возмещениях и претензиях клиентов
A21: Э6 | B21: Эффект в первый год работы (раскачка) | C21: доля | D21: 0.5 | E21: 0.5 | F21: 0.5 | G21: допущение | H21: Первый год — одна операция и постепенный перевод потока | I21: план тиражирования после пилота
A22: Б. Затраты ВТБ на внедрение и сравнение с собственной разработкой
A23: Б1 | B23: Полная стоимость ИТ-специалиста банка | C23: млн ₽ в год | D23: 4.5 | E23: 4.5 | F23: 4.5 | G23: допущение | H23: Оклад около 250 тыс. ₽ × 12 × 1,302 взносов × 1,15 накладных; вилки вакансий разработчиков 180–400 тыс. ₽ (S14) | I23: ставка внутреннего ИТ банка
A24: Б2 | B24: Интеграция силами банка (ДБО, источники, ИБ) | C24: человеко-лет | D24: 2 | E24: 1.5 | F24: 1 | G24: допущение | H24: Порты к источникам и OpenAPI готовы; банк подключает ДБО, реестр МЧД, ЕГРЮЛ и СКЗИ | I24: оценка ИТ-архитектора банка после пилота
A25: Б3 | B25: Инфраструктура в контуре банка, разово | C25: млн ₽ | D25: 2 | E25: 1.5 | F25: 1 | G25: допущение | H25: Два узла и резерв; ядро не требует GPU, модель для устава необязательна | I25: требования ИБ и эксплуатации банка
A26: Б4 | B26: Оценка ИБ силами банка, разово | C26: млн ₽ | D26: 1 | E26: 1 | F26: 1 | G26: допущение | H26: Внутренняя проверка документов ИБ, модели угроз и результатов анализа уязвимостей | I26: регламент ИБ банка
A27: Б5 | B27: Сопровождение силами банка | C27: человеко-лет в год | D27: 0.5 | E27: 0.5 | F27: 0.3 | G27: допущение | H27: Администрирование, обновления, разбор обращений; правила сопровождает поставщик | I27: регламент эксплуатации
A28: Б6 | B28: НДС на услуги внедрения (банк не принимает к вычету) | C28: доля | D28: 0.22 | E28: 0.22 | F28: 0.22 | G28: факт | H28: Ставка НДС 22 % с 01.01.2026; лицензия на ПО из реестра российского ПО освобождена (пп. 26 п. 2 ст. 149 НК РФ) — по обзорам (M-24, S12) | I28: налоговая политика банка
A29: Б7 | B29: Собственная разработка банка: создание | C29: человеко-лет | D29: 10 | E29: 10 | F29: 10 | G29: допущение | H29: Ядро правил, адаптеры, журнал, удостоверения, корпус тестов и юридическая разметка правил | I29: оценка ИТ банка
A30: Б8 | B30: Собственная разработка банка: сопровождение правил и кода | C30: человек | D30: 4 | E30: 4 | F30: 4 | G30: допущение | H30: Разработчик, юрист, аналитик, инженер качества | I30: оценка ИТ банка
A31: Б9 | B31: Горизонт сравнения «купить или сделать» | C31: лет | D31: 5 | E31: 5 | F31: 5 | G31: допущение | H31: Срок, на котором банк сравнивает варианты | I31: —
A32: Р. Рынок
A33: Р1 | B33: Действующих банков в России | C33: банков | D33: 301 | E33: 301 | F33: 301 | G33: вторичный | H33: 301 банк на 01.07.2026 без НКО (brobank.ru по данным Банка России, M-22, S10) | I33: таблица Банка России «Количественные характеристики банковского сектора»
A34: Р2 | B34: Уровень 1: системно значимые банки | C34: банков | D34: 12 | E34: 12 | F34: 12 | G34: вторичный | H34: Перечень СЗКО на 2026 год — 12 банков, около 80 % активов сектора (Moscow Times 07.10.2026, vbr.ru, M-21, S09) | I34: перечень на сайте Банка России
A35: Р3 | B35: Уровень 2: крупные и средние банки с корпоративным ДБО | C35: банков | D35: 48 | E35: 48 | F35: 48 | G35: допущение | H35: Банки с 13-го по 60-е место по активам; дальше — банки с малой базой бизнеса | I35: рэнкинг по активам и интервью с банками
A36: Р4 | B36: Доля ВТБ в отношениях «банк — клиент-бизнес» | C36: доля | D36: 0.2 | E36: 0.2 | F36: 0.2 | G36: допущение | H36: ВТБ называет клиентом «каждый третий реально действующий бизнес» (M-28, S15); у бизнеса бывает несколько банков, поэтому доля в отношениях ниже | I36: данные Банка России о счетах юрлиц и ИП
A37: Р5 | B37: Доля уровня 1 в отношениях с бизнесом | C37: доля | D37: 0.8 | E37: 0.8 | F37: 0.8 | G37: допущение | H37: Ориентир — доля СЗКО в активах сектора около 80 % (M-21) | I37: статистика Банка России по счетам
A38: Р6 | B38: Доля уровня 2 в отношениях с бизнесом | C38: доля | D38: 0.15 | E38: 0.15 | F38: 0.15 | G38: допущение | H38: Остаток после уровня 1; на уровень 3 приходится 5 % | I38: статистика Банка России по счетам
A39: Р7 | B39: Цена для банка уровня 3 через партнёра (всё включено) | C39: млн ₽ в год | D39: 0.3 | E39: 0.5 | F39: 0.7 | G39: гипотеза | H39: Небольшим банкам — через поставщиков ДБО; в SAM и SOM не входит | I39: переговоры с поставщиками ДБО
A40: Р8 | B40: Доля ценности задачи, которую забирает поставщик | C40: доля | D40: 0.1 | E40: 0.15 | F40: 0.2 | G40: допущение | H40: Обычная для корпоративного ПО доля 10–20 % измеренного эффекта клиента | I40: переговоры о цене после пилота
A41: Ц. Цена и продажи
...

Sheet План
A1: План продаж и команды
A2: Новые договоры и численность в ставках на конец года; 2026 — исходные значения
A4: № | B4: Показатель | C4: Единица | D4: Оклад 2027 | E4: 2026 | F4: 2027 | G4: 2028 | H4: 2029 | I4: 2030 | J4: 2031 | K4: Итого
A5: Консервативный
A6: КД1 | B6: Новые банки уровня 1 (кроме ВТБ) | C6: банков | E6: 0 | F6: 0 | G6: 0 | H6: 0 | I6: 0 | J6: 0 | K6: =SUM(F6:J6) -> 0
A7: КД2 | B7: Новые банки уровня 2 | C7: банков | E7: 0 | F7: 0 | G7: 0 | H7: 1 | I7: 1 | J7: 1 | K7: =SUM(F7:J7) -> 3
A8: КЧ1 | B8: Основатели: продукт и продажи, архитектура правил | C8: ставок | D8: 200 | E8: 2 | F8: 2 | G8: 2 | H8: 2 | I8: 2 | J8: 2
A9: КЧ2 | B9: Разработчики | C9: ставок | D9: 280 | E9: 0 | F9: 0 | G9: 1 | H9: 1 | I9: 1 | J9: 1
A10: КЧ3 | B10: Юрист-аналитик правил | C10: ставок | D10: 230 | E10: 0 | F10: 0.5 | G10: 0.5 | H10: 0.5 | I10: 0.5 | J10: 0.5
A11: КЧ4 | B11: Инженеры внедрения и поддержки | C11: ставок | D11: 220 | E11: 0 | F11: 0 | G11: 0 | H11: 0.5 | I11: 0.5 | J11: 0.5
A12: КЧ5 | B12: Инженер качества и ИБ | C12: ставок | D12: 250 | E12: 0 | F12: 0 | G12: 0 | H12: 0 | I12: 0 | J12: 0
A13: КЧ6 | B13: Менеджер по работе с банками | C13: ставок | D13: 220 | E13: 0 | F13: 0 | G13: 0 | H13: 0 | I13: 0 | J13: 0
A15: Базовый
A16: БД1 | B16: Новые банки уровня 1 (кроме ВТБ) | C16: банков | E16: 0 | F16: 0 | G16: 0 | H16: 1 | I16: 0 | J16: 1 | K16: =SUM(F16:J16) -> 2
A17: БД2 | B17: Новые банки уровня 2 | C17: банков | E17: 0 | F17: 0 | G17: 1 | H17: 2 | I17: 2 | J17: 3 | K17: =SUM(F17:J17) -> 8
A18: БЧ1 | B18: Основатели: продукт и продажи, архитектура правил | C18: ставок | D18: 200 | E18: 2 | F18: 2 | G18: 2 | H18: 2 | I18: 2 | J18: 2
A19: БЧ2 | B19: Разработчики | C19: ставок | D19: 280 | E19: 0 | F19: 1 | G19: 1 | H19: 1 | I19: 2 | J19: 2
A20: БЧ3 | B20: Юрист-аналитик правил | C20: ставок | D20: 230 | E20: 0 | F20: 1 | G20: 1 | H20: 1 | I20: 1 | J20: 1
A21: БЧ4 | B21: Инженеры внедрения и поддержки | C21: ставок | D21: 220 | E21: 0 | F21: 0 | G21: 1 | H21: 1 | I21: 1 | J21: 1
A22: БЧ5 | B22: Инженер качества и ИБ | C22: ставок | D22: 250 | E22: 0 | F22: 0 | G22: 0 | H22: 1 | I22: 1 | J22: 1
A23: БЧ6 | B23: Менеджер по работе с банками | C23: ставок | D23: 220 | E23: 0 | F23: 0 | G23: 0 | H23: 0 | I23: 0 | J23: 1
A25: Оптимистичный
A26: ОД1 | B26: Новые банки уровня 1 (кроме ВТБ) | C26: банков | E26: 0 | F26: 0 | G26: 0 | H26: 1 | I26: 1 | J26: 1 | K26: =SUM(F26:J26) -> 3
A27: ОД2 | B27: Новые банки уровня 2 | C27: банков | E27: 0 | F27: 0 | G27: 2 | H27: 3 | I27: 4 | J27: 5 | K27: =SUM(F27:J27) -> 14
A28: ОЧ1 | B28: Основатели: продукт и продажи, архитектура правил | C28: ставок | D28: 200 | E28: 2 | F28: 2 | G28: 2 | H28: 2 | I28: 2 | J28: 2
A29: ОЧ2 | B29: Разработчики | C29: ставок | D29: 280 | E29: 0 | F29: 1 | G29: 2 | H29: 3 | I29: 3 | J29: 4
A30: ОЧ3 | B30: Юрист-аналитик правил | C30: ставок | D30: 230 | E30: 0 | F30: 1 | G30: 1 | H30: 1 | I30: 2 | J30: 2
A31: ОЧ4 | B31: Инженеры внедрения и поддержки | C31: ставок | D31: 220 | E31: 0 | F31: 0 | G31: 1 | H31: 2 | I31: 3 | J31: 3
A32: ОЧ5 | B32: Инженер качества и ИБ | C32: ставок | D32: 250 | E32: 0 | F32: 0 | G32: 1 | H32: 1 | I32: 1 | J32: 2
A33: ОЧ6 | B33: Менеджер по работе с банками | C33: ставок | D33: 220 | E33: 0 | F33: 0 | G33: 0 | H33: 1 | I33: 1 | J33: 2
A35: Оклады 2027 года, тыс. ₽ в месяц до вычета налогов. Ориентиры: вакансии Python-разработчиков 180–300 тыс. ₽ (middle) и 300–400 тыс. ₽ (senior) на career.habr.com (S14); основатели — ниже рынка до выхода на прибыль.

Sheet Эффект для банка
A1: Эффект и окупаемость для ВТБ
A2: Ставки и ущерб повторяют расчёт презентации (C-15, C-16); деньги — млн ₽ в год без НДС, цены 2027 года
A4: № | B4: Показатель | C4: Единица | D4: Консервативный | E4: Базовый | F4: Оптимистичный | G4: Как считается
A5: Параметры (ссылки на «Допущения»)
A6: 1 | B6: Клиенты ВТБ — предприятия и предприниматели | C6: млн | D6: =Допущения!$D$7 -> 1.8 | E6: =Допущения!$E$7 -> 1.8 | F6: =Допущения!$F$7 -> 1.8 | G6: Допущения, строка П1
A7: 2 | B7: Доля клиентов со сменой или добавлением подписанта в год | C7: доля | D7: =Допущения!$D$8 -> 0.1 | E7: =Допущения!$E$8 -> 0.15 | F7: =Допущения!$F$8 -> 0.25 | G7: Допущения, строка П2
A8: 3 | B8: Минут на кейс вручную, вместе с разбором | C8: минут | D8: =Допущения!$D$9 -> 20 | E8: =Допущения!$E$9 -> 30 | F8: =Допущения!$F$9 -> 40 | G8: Допущения, строка П3
A9: 4 | B9: Рабочих часов на ставку в год | C9: часов | D9: =Допущения!$D$10 -> 1800 | E9: =Допущения!$E$10 -> 1800 | F9: =Допущения!$F$10 -> 1800 | G9: Допущения, строка П4
A10: 5 | B10: Операций без согласия у юрлиц за квартал | C10: операций | D10: =Допущения!$D$11 -> 818 | E10: =Допущения!$E$11 -> 818 | F10: =Допущения!$F$11 -> 818 | G10: Допущения, строка П5
A11: 6 | B11: Объём таких операций за квартал | C11: млн ₽ | D11: =Допущения!$D$12 -> 573 | E11: =Допущения!$E$12 -> 573 | F11: =Допущения!$F$12 -> 573 | G11: Допущения, строка П6
A12: 7 | B12: Доля ВТБ в таких инцидентах | C12: доля | D12: =Допущения!$D$13 -> 0.15 | E12: =Допущения!$E$13 -> 0.2 | F12: =Допущения!$F$13 -> 0.25 | G12: Допущения, строка П7
A13: 8 | B13: Доля инцидентов, связанных с полномочиями | C13: доля | D13: =Допущения!$D$14 -> 0.1 | E13: =Допущения!$E$14 -> 0.25 | F13: =Допущения!$F$14 -> 0.4 | G13: Допущения, строка П8
A14: 9 | B14: Оклад сотрудника, проверяющего документы | C14: тыс. ₽ в месяц | D14: =Допущения!$D$16 -> 85 | E14: =Допущения!$E$16 -> 100 | F14: =Допущения!$F$16 -> 120 | G14: Допущения, строка Э1
A15: 10 | B15: Страховые взносы банка | C15: доля | D15: =Допущения!$D$17 -> 0.302 | E15: =Допущения!$E$17 -> 0.302 | F15: =Допущения!$F$17 -> 0.302 | G15: Допущения, строка Э2
A16: 11 | B16: Накладные на рабочее место (помещение, ИТ, управление) | C16: доля к ФОТ с взносами | D16: =Допущения!$D$18 -> 0.2 | E16: =Допущения!$E$18 -> 0.25 | F16: =Допущения!$F$18 -> 0.3 | G16: Допущения, строка Э3
A17: 12 | B17: Доля высвобожденного времени, которая становится экономией | C17: доля | D17: =Допущения!$D$19 -> 0.3 | E17: =Допущения!$E$19 -> 0.5 | F17: =Допущения!$F$19 -> 0.7 | G17: Допущения, строка Э4
A18: 13 | B18: Доля предотвращённого ущерба клиентов, которую несёт банк | C18: доля | D18: =Допущения!$D$20 -> 0.1 | E18: =Допущения!$E$20 -> 0.159 | F18: =Допущения!$F$20 -> 0.25 | G18: Допущения, строка Э5
A19: 14 | B19: Эффект в первый год работы (раскачка) | C19: доля | D19: =Допущения!$D$21 -> 0.5 | E19: =Допущения!$E$21 -> 0.5 | F19: =Допущения!$F$21 -> 0.5 | G19: Допущения, строка Э6
A20: 15 | B20: Подписка банка уровня 1: постоянная часть | C20: млн ₽ в год | D20: =Допущения!$D$42 -> 3 | E20: =Допущения!$E$42 -> 6 | F20: =Допущения!$F$42 -> 8 | G20: Допущения, строка Ц1
A21: 16 | B21: Подписка: плата за активного клиента-бизнес | C21: ₽ в год | D21: =Допущения!$D$43 -> 2 | E21: =Допущения!$E$43 -> 5 | F21: =Допущения!$F$43 -> 7 | G21: Допущения, строка Ц2
A22: 17 | B22: Внедрение в банке уровня 1, разово | C22: млн ₽ | D22: =Допущения!$D$45 -> 6 | E22: =Допущения!$E$45 -> 8 | F22: =Допущения!$F$45 -> 10 | G22: Допущения, строка Ц4
A23: 18 | B23: НДС на услуги внедрения (банк не принимает к вычету) | C23: доля | D23: =Допущения!$D$28 -> 0.22 | E23: =Допущения!$E$28 -> 0.22 | F23: =Допущения!$F$28 -> 0.22 | G23: Допущения, строка Б6
A24: 19 | B24: Полная стоимость ИТ-специалиста банка | C24: млн ₽ в год | D24: =Допущения!$D$23 -> 4.5 | E24: =Допущения!$E$23 -> 4.5 | F24: =Допущения!$F$23 -> 4.5 | G24: Допущения, строка Б1
A25: 20 | B25: Интеграция силами банка (ДБО, источники, ИБ) | C25: человеко-лет | D25: =Допущения!$D$24 -> 2 | E25: =Допущения!$E$24 -> 1.5 | F25: =Допущения!$F$24 -> 1 | G25: Допущения, строка Б2
A26: 21 | B26: Инфраструктура в контуре банка, разово | C26: млн ₽ | D26: =Допущения!$D$25 -> 2 | E26: =Допущения!$E$25 -> 1.5 | F26: =Допущения!$F$25 -> 1 | G26: Допущения, строка Б3
A27: 22 | B27: Оценка ИБ силами банка, разово | C27: млн ₽ | D27: =Допущения!$D$26 -> 1 | E27: =Допущения!$E$26 -> 1 | F27: =Допущения!$F$26 -> 1 | G27: Допущения, строка Б4
A28: 23 | B28: Сопровождение силами банка | C28: человеко-лет в год | D28: =Допущения!$D$27 -> 0.5 | E28: =Допущения!$E$27 -> 0.5 | F28: =Допущения!$F$27 -> 0.3 | G28: Допущения, строка Б5
A29: 24 | B29: Собственная разработка банка: создание | C29: человеко-лет | D29: =Допущения!$D$29 -> 10 | E29: =Допущения!$E$29 -> 10 | F29: =Допущения!$F$29 -> 10 | G29: Допущения, строка Б7
A30: 25 | B30: Собственная разработка банка: сопровождение правил и кода | C30: человек | D30: =Допущения!$D$30 -> 4 | E30: =Допущения!$E$30 -> 4 | F30: =Допущения!$F$30 -> 4 | G30: Допущения, строка Б8
A31: 26 | B31: Горизонт сравнения «купить или сделать» | C31: лет | D31: =Допущения!$D$31 -> 5 | E31: =Допущения!$E$31 -> 5 | F31: =Допущения!$F$31 -> 5 | G31: Допущения, строка Б9
A32: 1. Высвобождение времени
A33: 27 | B33: Кейсов смены или добавления подписанта в год | C33: тыс. | D33: =D6*1000*D7 -> 180 | E33: =E6*1000*E7 -> 270 | F33: =F6*1000*F7 -> 450 | G33: клиенты × доля с событием
A34: 28 | B34: Часов ручной проверки в год | C34: тыс. часов | D34: =D33*D8/60 -> 60 | E34: =E33*E8/60 -> 135 | F34: =F33*F8/60 -> 300 | G34: кейсы × минуты / 60
A35: 29 | B35: Высвобождается ставок | C35: ставок | D35: =D34*1000/D9 -> 33.333333 | E35: =E34*1000/E9 -> 75 | F35: =F34*1000/F9 -> 166.66667 | G35: часы / часы на ставку
A36: 30 | B36: То же, округлено (как в презентации, C-15) | C36: ставок | D36: =ROUND(D35,0) -> 33 | E36: =ROUND(E35,0) -> 75 | F36: =ROUND(F35,0) -> 167 | G36: сверяется на листе «Проверки»
A37: 31 | B37: Полная стоимость ставки | C37: млн ₽ в год | D37: =D14*12*(1+D15)*(1+D16)/1000 -> 1.593648 | E37: =E14*12*(1+E15)*(1+E16)/1000 -> 1.953 | F37: =F14*12*(1+F15)*(1+F16)/1000 -> 2.437344 | G37: оклад × 12 × (1 + взносы) × (1 + накладные)
A38: 32 | B38: Стоимость высвобожденного времени (ёмкость) | C38: млн ₽ в год | D38: =D35*D37 -> 53.1216 | E38: =E35*E37 -> 146.475 | F38: =F35*F37 -> 406.224 | G38: ставки × стоимость ставки
A39: 33 | B39: Денежная экономия на времени | C39: млн ₽ в год | D39: =D38*D17 -> 15.93648 | E39: =E38*E17 -> 73.2375 | F39: =F38*F17 -> 284.3568 | G39: ёмкость × доля, которая становится экономией
A40: 2. Предотвращённый ущерб
A41: 34 | B41: Средняя операция без согласия у юрлица | C41: млн ₽ | D41: =D11/D10 -> 0.700489 | E41: =E11/E10 -> 0.700489 | F41: =F11/F10 -> 0.700489 | G41: объём за квартал / число операций
...

Sheet Рынок
A1: Объём рынка: банки России
A2: Снизу вверх — банки по уровням × цена подписки; сверху вниз — ценность задачи × доля поставщика. Млн ₽ в год без НДС, цены 2027 года
A4: № | B4: Показатель | C4: Единица | D4: Консервативный | E4: Базовый | F4: Оптимистичный | G4: Как считается
A5: Параметры (ссылки на «Допущения» и «Эффект для банка»)
A6: 1 | B6: Действующих банков в России | C6: банков | D6: =Допущения!$D$33 -> 301 | E6: =Допущения!$E$33 -> 301 | F6: =Допущения!$F$33 -> 301 | G6: Допущения, строка Р1
A7: 2 | B7: Уровень 1: системно значимые банки | C7: банков | D7: =Допущения!$D$34 -> 12 | E7: =Допущения!$E$34 -> 12 | F7: =Допущения!$F$34 -> 12 | G7: Допущения, строка Р2
A8: 3 | B8: Уровень 2: крупные и средние банки с корпоративным ДБО | C8: банков | D8: =Допущения!$D$35 -> 48 | E8: =Допущения!$E$35 -> 48 | F8: =Допущения!$F$35 -> 48 | G8: Допущения, строка Р3
A9: 4 | B9: Доля ВТБ в отношениях «банк — клиент-бизнес» | C9: доля | D9: =Допущения!$D$36 -> 0.2 | E9: =Допущения!$E$36 -> 0.2 | F9: =Допущения!$F$36 -> 0.2 | G9: Допущения, строка Р4
A10: 5 | B10: Доля уровня 1 в отношениях с бизнесом | C10: доля | D10: =Допущения!$D$37 -> 0.8 | E10: =Допущения!$E$37 -> 0.8 | F10: =Допущения!$F$37 -> 0.8 | G10: Допущения, строка Р5
A11: 6 | B11: Доля уровня 2 в отношениях с бизнесом | C11: доля | D11: =Допущения!$D$38 -> 0.15 | E11: =Допущения!$E$38 -> 0.15 | F11: =Допущения!$F$38 -> 0.15 | G11: Допущения, строка Р6
A12: 7 | B12: Цена для банка уровня 3 через партнёра (всё включено) | C12: млн ₽ в год | D12: =Допущения!$D$39 -> 0.3 | E12: =Допущения!$E$39 -> 0.5 | F12: =Допущения!$F$39 -> 0.7 | G12: Допущения, строка Р7
A13: 8 | B13: Доля ценности задачи, которую забирает поставщик | C13: доля | D13: =Допущения!$D$40 -> 0.1 | E13: =Допущения!$E$40 -> 0.15 | F13: =Допущения!$F$40 -> 0.2 | G13: Допущения, строка Р8
A14: 9 | B14: Клиенты ВТБ — предприятия и предприниматели | C14: млн | D14: =Допущения!$D$7 -> 1.8 | E14: =Допущения!$E$7 -> 1.8 | F14: =Допущения!$F$7 -> 1.8 | G14: Допущения, строка П1
A15: 10 | B15: Подписка банка уровня 1: постоянная часть | C15: млн ₽ в год | D15: =Допущения!$D$42 -> 3 | E15: =Допущения!$E$42 -> 6 | F15: =Допущения!$F$42 -> 8 | G15: Допущения, строка Ц1
A16: 11 | B16: Подписка банка уровня 2: постоянная часть | C16: млн ₽ в год | D16: =Допущения!$D$44 -> 1 | E16: =Допущения!$E$44 -> 1.5 | F16: =Допущения!$F$44 -> 2 | G16: Допущения, строка Ц3
A17: 12 | B17: Подписка: плата за активного клиента-бизнес | C17: ₽ в год | D17: =Допущения!$D$43 -> 2 | E17: =Допущения!$E$43 -> 5 | F17: =Допущения!$F$43 -> 7 | G17: Допущения, строка Ц2
A18: 13 | B18: Рост подписки банка за счёт новых операций | C18: доля в год | D18: =Допущения!$D$48 -> 0 | E18: =Допущения!$E$48 -> 0.15 | F18: =Допущения!$F$48 -> 0.25 | G18: Допущения, строка Ц7
A19: 14 | B19: Операций без согласия у юрлиц за квартал | C19: операций | D19: =Допущения!$D$11 -> 818 | E19: =Допущения!$E$11 -> 818 | F19: =Допущения!$F$11 -> 818 | G19: Допущения, строка П5
A20: 15 | B20: Доля инцидентов, связанных с полномочиями | C20: доля | D20: =Допущения!$D$14 -> 0.1 | E20: =Допущения!$E$14 -> 0.25 | F20: =Допущения!$F$14 -> 0.4 | G20: Допущения, строка П8
A21: 16 | B21: Доля предотвращённого ущерба клиентов, которую несёт банк | C21: доля | D21: =Допущения!$D$20 -> 0.1 | E21: =Допущения!$E$20 -> 0.159 | F21: =Допущения!$F$20 -> 0.25 | G21: Допущения, строка Э5
A22: 17 | B22: Стоимость высвобожденного времени ВТБ | C22: млн ₽ в год | D22: ='Эффект для банка'!$D$38 -> 53.1216 | E22: ='Эффект для банка'!$E$38 -> 146.475 | F22: ='Эффект для банка'!$F$38 -> 406.224 | G22: лист «Эффект для банка»
A23: 18 | B23: Средняя операция без согласия | C23: млн ₽ | D23: ='Эффект для банка'!$D$41 -> 0.700489 | E23: ='Эффект для банка'!$E$41 -> 0.700489 | F23: ='Эффект для банка'!$F$41 -> 0.700489 | G23: лист «Эффект для банка»
A24: 1. Банки и клиенты-бизнесы
A25: 19 | B25: Уровень 3: остальные банки | C25: банков | D25: =D6-D7-D8 -> 241 | E25: =E6-E7-E8 -> 241 | F25: =F6-F7-F8 -> 241 | G25: всего − уровень 1 − уровень 2
A26: 20 | B26: Отношений «банк — клиент-бизнес» в России | C26: млн | D26: =D14/D9 -> 9 | E26: =E14/E9 -> 9 | F26: =F14/F9 -> 9 | G26: клиенты ВТБ / доля ВТБ
A27: 21 | B27: Из них в банках уровня 1 | C27: млн | D27: =D26*D10 -> 7.2 | E27: =E26*E10 -> 7.2 | F27: =F26*F10 -> 7.2 | G27: всего × доля уровня 1
A28: 22 | B28: В банках уровня 2 | C28: млн | D28: =D26*D11 -> 1.35 | E28: =E26*E11 -> 1.35 | F28: =F26*F11 -> 1.35 | G28: всего × доля уровня 2
A29: 23 | B29: В банках уровня 3 | C29: млн | D29: =D26-D27-D28 -> 0.45 | E29: =E26-E27-E28 -> 0.45 | F29: =F26-F27-F28 -> 0.45 | G29: остаток
A30: 24 | B30: Клиентов-бизнесов у банка уровня 1, кроме ВТБ, в среднем | C30: млн | D30: =(D27-D14)/(D7-1) -> 0.49090909 | E30: =(E27-E14)/(E7-1) -> 0.49090909 | F30: =(F27-F14)/(F7-1) -> 0.49090909 | G30: (уровень 1 − ВТБ) / (банков уровня 1 − 1); база для подписки других банков
A31: 25 | B31: Клиентов-бизнесов у банка уровня 2 в среднем | C31: млн | D31: =D28/D8 -> 0.028125 | E31: =E28/E8 -> 0.028125 | F31: =F28/F8 -> 0.028125 | G31: уровень 2 / банков уровня 2
A32: 2. Снизу вверх: все банки по прайсу
A33: 26 | B33: Уровень 1 | C33: млн ₽ в год | D33: =D7*D15+D27*D17 -> 50.4 | E33: =E7*E15+E27*E17 -> 108 | F33: =F7*F15+F27*F17 -> 146.4 | G33: банки × постоянная часть + клиенты × плата за клиента
A34: 27 | B34: Уровень 2 | C34: млн ₽ в год | D34: =D8*D16+D28*D17 -> 50.7 | E34: =E8*E16+E28*E17 -> 78.75 | F34: =F8*F16+F28*F17 -> 105.45 | G34: то же
A35: 28 | B35: Уровень 3 (через партнёров) | C35: млн ₽ в год | D35: =D25*D12 -> 72.3 | E35: =E25*E12 -> 120.5 | F35: =F25*F12 -> 168.7 | G35: банки × цена через партнёра
A36: 29 | B36: TAM: все банки России | C36: млн ₽ в год | D36: =D33+D34+D35 -> 173.4 | E36: =E33+E34+E35 -> 307.25 | F36: =F33+F34+F35 -> 420.55 | G36: сумма уровней
A37: 30 | B37: SAM: банки уровней 1 и 2 (установка в контуре) | C37: млн ₽ в год | D37: =D33+D34 -> 101.1 | E37: =E33+E34 -> 186.75 | F37: =F33+F34 -> 251.85 | G37: уровни, которые обслуживаем сами
A38: 31 | B38: Подписка при полном охвате операций, к одной операции | C38: раз | D38: =(1+D18)^4 -> 1 | E38: =(1+E18)^4 -> 1.7490063 | F38: =(1+F18)^4 -> 2.4414062 | G38: банк добавляет операции четыре года: (1 + рост подписки) ^ 4
A39: 32 | B39: TAM при полном охвате операций | C39: млн ₽ в год | D39: =D36*D38 -> 173.4 | E39: =E36*E38 -> 537.38217 | F39: =F36*F38 -> 1026.7334 | G39: TAM × множитель
A40: 33 | B40: SAM при полном охвате операций | C40: млн ₽ в год | D40: =D37*D38 -> 101.1 | E40: =E37*E38 -> 326.62692 | F40: =F37*F38 -> 614.86816 | G40: SAM × множитель
A41: 3. SOM: годовая подписка на конец 2031 года по плану продаж
...

Sheet Консервативный
A1: Расчёт: консервативный сценарий
A2: Входы — зелёные ссылки на «Допущения», «План» и «Рынок»; в строке одна формула для всех лет; млн ₽ без НДС
A4: № | B4: Показатель | C4: Единица | D4: Константа | E4: 2026 | F4: 2027 | G4: 2028 | H4: 2029 | I4: 2030 | J4: 2031 | K4: Итого 2027–2031 | L4: Как считается
A5: Входные данные (ссылки на «Допущения», «План», «Рынок»)
A6: 1 | B6: Год договора с ВТБ | C6: год | D6: =Допущения!$D$49 -> 2028
A7: 2 | B7: Клиенты-бизнесы ВТБ | C7: млн | D7: =Допущения!$D$7 -> 1.8
A8: 3 | B8: Подписка уровня 1: постоянная часть | C8: млн ₽ в год | D8: =Допущения!$D$42 -> 3
A9: 4 | B9: Плата за активного клиента-бизнес | C9: ₽ в год | D9: =Допущения!$D$43 -> 2
A10: 5 | B10: Подписка уровня 2: постоянная часть | C10: млн ₽ в год | D10: =Допущения!$D$44 -> 1
A11: 6 | B11: Внедрение, уровень 1 | C11: млн ₽ | D11: =Допущения!$D$45 -> 6
A12: 7 | B12: Внедрение, уровень 2 | C12: млн ₽ | D12: =Допущения!$D$46 -> 1.5
A13: 8 | B13: Индексация цен | C13: доля в год | D13: =Допущения!$D$47 -> 0.04
A14: 9 | B14: Рост подписки за счёт новых операций | C14: доля в год | D14: =Допущения!$D$48 -> 0
A15: 10 | B15: Рост окладов | C15: доля в год | D15: =Допущения!$D$51 -> 0.07
A16: 11 | B16: Взносы в пределах базы | C16: доля | D16: =Допущения!$D$52 -> 0.15
A17: 12 | B17: Взносы сверх базы | C17: доля | D17: =Допущения!$D$53 -> 0.076
A18: 13 | B18: Взнос на травматизм | C18: доля | D18: =Допущения!$D$54 -> 0.002
A19: 14 | B19: Предельная база взносов 2026 | C19: млн ₽ в год | D19: =Допущения!$D$55 -> 2.979
A20: 15 | B20: Рост базы | C20: доля в год | D20: =Допущения!$D$56 -> 0.08
A21: 16 | B21: Анализ уязвимостей по ОУД4 — первый | C21: млн ₽ | D21: =Допущения!$D$58 -> 3
A22: 17 | B22: Повторная оценка релизов | C22: млн ₽ в год | D22: =Допущения!$D$59 -> 1.2
A23: 18 | B23: Внешняя юридическая экспертиза правил | C23: млн ₽ в год | D23: =Допущения!$D$60 -> 0.4
A24: 19 | B24: Инфраструктура на сотрудника | C24: млн ₽ в год | D24: =Допущения!$D$61 -> 0.12
A25: 20 | B25: Продажи: постоянная часть | C25: млн ₽ в год | D25: =Допущения!$D$62 -> 0.6
A26: 21 | B26: Продажи: на договор | C26: млн ₽ | D26: =Допущения!$D$63 -> 0.3
A27: 22 | B27: Административные: постоянная часть | C27: млн ₽ в год | D27: =Допущения!$D$64 -> 1
A28: 23 | B28: Административные: на сотрудника | C28: млн ₽ в год | D28: =Допущения!$D$65 -> 0.08
A29: 24 | B29: Оборудование на нового сотрудника | C29: млн ₽ | D29: =Допущения!$D$66 -> 0.25
A30: 25 | B30: Регистрация, аккредитация, реестр ПО | C30: млн ₽ | D30: =Допущения!$D$67 -> 0.3
A31: 26 | B31: Рост прочих затрат | C31: доля в год | D31: =Допущения!$D$68 -> 0.05
A32: 27 | B32: Резерв | C32: доля затрат | D32: =Допущения!$D$69 -> 0.1
A33: 28 | B33: Налог на прибыль | C33: доля | D33: =Допущения!$D$71 -> 0.05
A34: 29 | B34: Перенос убытка: доля прибыли | C34: доля | D34: =Допущения!$D$72 -> 0.5
A35: 30 | B35: Срок оплаты банками | C35: дней | D35: =Допущения!$D$73 -> 120
A36: 31 | B36: Ставка дисконтирования | C36: доля | D36: =Допущения!$D$74 -> 0.3
A37: 32 | B37: Рост после 2031 года | C37: доля в год | D37: =Допущения!$D$75 -> 0.04
A38: 33 | B38: Запас к финансированию | C38: доля | D38: =Допущения!$D$76 -> 0.2
A39: 34 | B39: Клиентов у банка уровня 1, кроме ВТБ | C39: млн | D39: =Рынок!$D$30 -> 0.49090909 | L39: лист «Рынок»
A40: 35 | B40: Клиентов у банка уровня 2 | C40: млн | D40: =Рынок!$D$31 -> 0.028125 | L40: лист «Рынок»
A41: 36 | B41: Оклад: Основатели: продукт и продажи, архитектура правил | C41: тыс. ₽ в месяц | D41: =План!$D$8 -> 200 | L41: лист «План»
...

Sheet Базовый
A1: Расчёт: базовый сценарий
A2: Входы — зелёные ссылки на «Допущения», «План» и «Рынок»; в строке одна формула для всех лет; млн ₽ без НДС
A4: № | B4: Показатель | C4: Единица | D4: Константа | E4: 2026 | F4: 2027 | G4: 2028 | H4: 2029 | I4: 2030 | J4: 2031 | K4: Итого 2027–2031 | L4: Как считается
A5: Входные данные (ссылки на «Допущения», «План», «Рынок»)
A6: 1 | B6: Год договора с ВТБ | C6: год | D6: =Допущения!$E$49 -> 2027
A7: 2 | B7: Клиенты-бизнесы ВТБ | C7: млн | D7: =Допущения!$E$7 -> 1.8
A8: 3 | B8: Подписка уровня 1: постоянная часть | C8: млн ₽ в год | D8: =Допущения!$E$42 -> 6
A9: 4 | B9: Плата за активного клиента-бизнес | C9: ₽ в год | D9: =Допущения!$E$43 -> 5
A10: 5 | B10: Подписка уровня 2: постоянная часть | C10: млн ₽ в год | D10: =Допущения!$E$44 -> 1.5
A11: 6 | B11: Внедрение, уровень 1 | C11: млн ₽ | D11: =Допущения!$E$45 -> 8
A12: 7 | B12: Внедрение, уровень 2 | C12: млн ₽ | D12: =Допущения!$E$46 -> 2
A13: 8 | B13: Индексация цен | C13: доля в год | D13: =Допущения!$E$47 -> 0.05
A14: 9 | B14: Рост подписки за счёт новых операций | C14: доля в год | D14: =Допущения!$E$48 -> 0.15
A15: 10 | B15: Рост окладов | C15: доля в год | D15: =Допущения!$E$51 -> 0.07
A16: 11 | B16: Взносы в пределах базы | C16: доля | D16: =Допущения!$E$52 -> 0.15
A17: 12 | B17: Взносы сверх базы | C17: доля | D17: =Допущения!$E$53 -> 0.076
A18: 13 | B18: Взнос на травматизм | C18: доля | D18: =Допущения!$E$54 -> 0.002
A19: 14 | B19: Предельная база взносов 2026 | C19: млн ₽ в год | D19: =Допущения!$E$55 -> 2.979
A20: 15 | B20: Рост базы | C20: доля в год | D20: =Допущения!$E$56 -> 0.08
A21: 16 | B21: Анализ уязвимостей по ОУД4 — первый | C21: млн ₽ | D21: =Допущения!$E$58 -> 2.5
A22: 17 | B22: Повторная оценка релизов | C22: млн ₽ в год | D22: =Допущения!$E$59 -> 1
A23: 18 | B23: Внешняя юридическая экспертиза правил | C23: млн ₽ в год | D23: =Допущения!$E$60 -> 0.6
A24: 19 | B24: Инфраструктура на сотрудника | C24: млн ₽ в год | D24: =Допущения!$E$61 -> 0.15
A25: 20 | B25: Продажи: постоянная часть | C25: млн ₽ в год | D25: =Допущения!$E$62 -> 1
A26: 21 | B26: Продажи: на договор | C26: млн ₽ | D26: =Допущения!$E$63 -> 0.4
A27: 22 | B27: Административные: постоянная часть | C27: млн ₽ в год | D27: =Допущения!$E$64 -> 1.2
A28: 23 | B28: Административные: на сотрудника | C28: млн ₽ в год | D28: =Допущения!$E$65 -> 0.1
A29: 24 | B29: Оборудование на нового сотрудника | C29: млн ₽ | D29: =Допущения!$E$66 -> 0.25
A30: 25 | B30: Регистрация, аккредитация, реестр ПО | C30: млн ₽ | D30: =Допущения!$E$67 -> 0.3
A31: 26 | B31: Рост прочих затрат | C31: доля в год | D31: =Допущения!$E$68 -> 0.05
A32: 27 | B32: Резерв | C32: доля затрат | D32: =Допущения!$E$69 -> 0.1
A33: 28 | B33: Налог на прибыль | C33: доля | D33: =Допущения!$E$71 -> 0.05
A34: 29 | B34: Перенос убытка: доля прибыли | C34: доля | D34: =Допущения!$E$72 -> 0.5
A35: 30 | B35: Срок оплаты банками | C35: дней | D35: =Допущения!$E$73 -> 90
A36: 31 | B36: Ставка дисконтирования | C36: доля | D36: =Допущения!$E$74 -> 0.3
A37: 32 | B37: Рост после 2031 года | C37: доля в год | D37: =Допущения!$E$75 -> 0.04
A38: 33 | B38: Запас к финансированию | C38: доля | D38: =Допущения!$E$76 -> 0.2
A39: 34 | B39: Клиентов у банка уровня 1, кроме ВТБ | C39: млн | D39: =Рынок!$E$30 -> 0.49090909 | L39: лист «Рынок»
A40: 35 | B40: Клиентов у банка уровня 2 | C40: млн | D40: =Рынок!$E$31 -> 0.028125 | L40: лист «Рынок»
A41: 36 | B41: Оклад: Основатели: продукт и продажи, архитектура правил | C41: тыс. ₽ в месяц | D41: =План!$D$18 -> 200 | L41: лист «План»
...

Sheet Оптимистичный
A1: Расчёт: оптимистичный сценарий
A2: Входы — зелёные ссылки на «Допущения», «План» и «Рынок»; в строке одна формула для всех лет; млн ₽ без НДС
A4: № | B4: Показатель | C4: Единица | D4: Константа | E4: 2026 | F4: 2027 | G4: 2028 | H4: 2029 | I4: 2030 | J4: 2031 | K4: Итого 2027–2031 | L4: Как считается
A5: Входные данные (ссылки на «Допущения», «План», «Рынок»)
A6: 1 | B6: Год договора с ВТБ | C6: год | D6: =Допущения!$F$49 -> 2027
A7: 2 | B7: Клиенты-бизнесы ВТБ | C7: млн | D7: =Допущения!$F$7 -> 1.8
A8: 3 | B8: Подписка уровня 1: постоянная часть | C8: млн ₽ в год | D8: =Допущения!$F$42 -> 8
A9: 4 | B9: Плата за активного клиента-бизнес | C9: ₽ в год | D9: =Допущения!$F$43 -> 7
A10: 5 | B10: Подписка уровня 2: постоянная часть | C10: млн ₽ в год | D10: =Допущения!$F$44 -> 2
A11: 6 | B11: Внедрение, уровень 1 | C11: млн ₽ | D11: =Допущения!$F$45 -> 10
A12: 7 | B12: Внедрение, уровень 2 | C12: млн ₽ | D12: =Допущения!$F$46 -> 2.5
A13: 8 | B13: Индексация цен | C13: доля в год | D13: =Допущения!$F$47 -> 0.06
A14: 9 | B14: Рост подписки за счёт новых операций | C14: доля в год | D14: =Допущения!$F$48 -> 0.25
A15: 10 | B15: Рост окладов | C15: доля в год | D15: =Допущения!$F$51 -> 0.07
A16: 11 | B16: Взносы в пределах базы | C16: доля | D16: =Допущения!$F$52 -> 0.15
A17: 12 | B17: Взносы сверх базы | C17: доля | D17: =Допущения!$F$53 -> 0.076
A18: 13 | B18: Взнос на травматизм | C18: доля | D18: =Допущения!$F$54 -> 0.002
A19: 14 | B19: Предельная база взносов 2026 | C19: млн ₽ в год | D19: =Допущения!$F$55 -> 2.979
A20: 15 | B20: Рост базы | C20: доля в год | D20: =Допущения!$F$56 -> 0.08
A21: 16 | B21: Анализ уязвимостей по ОУД4 — первый | C21: млн ₽ | D21: =Допущения!$F$58 -> 2.5
A22: 17 | B22: Повторная оценка релизов | C22: млн ₽ в год | D22: =Допущения!$F$59 -> 1
A23: 18 | B23: Внешняя юридическая экспертиза правил | C23: млн ₽ в год | D23: =Допущения!$F$60 -> 0.8
A24: 19 | B24: Инфраструктура на сотрудника | C24: млн ₽ в год | D24: =Допущения!$F$61 -> 0.18
A25: 20 | B25: Продажи: постоянная часть | C25: млн ₽ в год | D25: =Допущения!$F$62 -> 1.5
A26: 21 | B26: Продажи: на договор | C26: млн ₽ | D26: =Допущения!$F$63 -> 0.5
A27: 22 | B27: Административные: постоянная часть | C27: млн ₽ в год | D27: =Допущения!$F$64 -> 1.5
A28: 23 | B28: Административные: на сотрудника | C28: млн ₽ в год | D28: =Допущения!$F$65 -> 0.12
A29: 24 | B29: Оборудование на нового сотрудника | C29: млн ₽ | D29: =Допущения!$F$66 -> 0.25
A30: 25 | B30: Регистрация, аккредитация, реестр ПО | C30: млн ₽ | D30: =Допущения!$F$67 -> 0.3
A31: 26 | B31: Рост прочих затрат | C31: доля в год | D31: =Допущения!$F$68 -> 0.05
A32: 27 | B32: Резерв | C32: доля затрат | D32: =Допущения!$F$69 -> 0.1
A33: 28 | B33: Налог на прибыль | C33: доля | D33: =Допущения!$F$71 -> 0.05
A34: 29 | B34: Перенос убытка: доля прибыли | C34: доля | D34: =Допущения!$F$72 -> 0.5
A35: 30 | B35: Срок оплаты банками | C35: дней | D35: =Допущения!$F$73 -> 60
A36: 31 | B36: Ставка дисконтирования | C36: доля | D36: =Допущения!$F$74 -> 0.3
A37: 32 | B37: Рост после 2031 года | C37: доля в год | D37: =Допущения!$F$75 -> 0.04
A38: 33 | B38: Запас к финансированию | C38: доля | D38: =Допущения!$F$76 -> 0.2
A39: 34 | B39: Клиентов у банка уровня 1, кроме ВТБ | C39: млн | D39: =Рынок!$F$30 -> 0.49090909 | L39: лист «Рынок»
A40: 35 | B40: Клиентов у банка уровня 2 | C40: млн | D40: =Рынок!$F$31 -> 0.028125 | L40: лист «Рынок»
A41: 36 | B41: Оклад: Основатели: продукт и продажи, архитектура правил | C41: тыс. ₽ в месяц | D41: =План!$D$28 -> 200 | L41: лист «План»
...

Sheet Чувствительность
A1: Чувствительность NPV базового сценария
A2: Каждое допущение меняется на ±20 %, остальные — как в базовом сценарии. Блоки расчёта ниже — та же структура, что на листе «Базовый»
A4: № | B4: Допущение | C4: Изменение | D4: NPV при −20 % | E4: NPV при +20 % | F4: Базовый NPV | G4: Размах
A5: 1 | B5: Цена подписки | C5: ±20 % | D5: =$D$290 -> -18.213264 | E5: =$D$429 -> 17.452316 | F5: =Базовый!$D$136 -> -0.14959473 | G5: =ABS(E5-D5) -> 35.665579
A6: 2 | B6: Число новых банков | C6: ±20 % | D6: =$D$568 -> -11.087652 | E6: =$D$707 -> 10.778634 | F6: =Базовый!$D$136 -> -0.14959473 | G6: =ABS(E6-D6) -> 21.866287
A7: 3 | B7: Рост подписки за счёт новых операций | C7: ±20 % | D7: =$D$846 -> -3.7113142 | E7: =$D$985 -> 3.5450611 | F7: =Базовый!$D$136 -> -0.14959473 | G7: =ABS(E7-D7) -> 7.2563753
A8: 4 | B8: Плата за внедрение | C8: ±20 % | D8: =$D$1124 -> -6.5416818 | E8: =$D$1263 -> 6.2334685 | F8: =Базовый!$D$136 -> -0.14959473 | G8: =ABS(E8-D8) -> 12.77515
A9: 5 | B9: Оклады команды | C9: ±20 % | D9: =$D$1402 -> 17.70952 | E9: =$D$1541 -> -18.179021 | F9: =Базовый!$D$136 -> -0.14959473 | G9: =ABS(E9-D9) -> 35.888541
A10: 6 | B10: Численность команды | C10: ±20 % | D10: =$D$1680 -> 19.2436 | E10: =$D$1819 -> -20.205538 | F10: =Базовый!$D$136 -> -0.14959473 | G10: =ABS(E10-D10) -> 39.449138
A11: 7 | B11: Прочие затраты | C11: ±20 % | D11: =$D$1958 -> 5.8850866 | E11: =$D$2097 -> -6.1842761 | F11: =Базовый!$D$136 -> -0.14959473 | G11: =ABS(E11-D11) -> 12.069363
A12: 8 | B12: Срок оплаты банками | C12: ±20 % | D12: =$D$2236 -> 2.5870315 | E12: =$D$2375 -> -2.886221 | F12: =Базовый!$D$136 -> -0.14959473 | G12: =ABS(E12-D12) -> 5.4732525
A13: 9 | B13: Ставка дисконтирования | C13: ±20 % | D13: =$D$2514 -> 9.0779508 | E13: =$D$2653 -> -4.9603535 | F13: =Базовый!$D$136 -> -0.14959473 | G13: =ABS(E13-D13) -> 14.038304
A14: 10 | B14: Договор с ВТБ на год позже | C14: +1 год | D14: =$D$2792 -> -15.249814 | F14: =Базовый!$D$136 -> -0.14959473 | G14: =ABS(D14-F14) -> 15.100219
A16: Строки с блоками расчёта свёрнуты: раскройте группу слева, чтобы увидеть формулы.
A18: Контроль: базовый сценарий без изменений
A19: № | B19: Показатель | C19: Единица | D19: Константа | E19: 2026 | F19: 2027 | G19: 2028 | H19: 2029 | I19: 2030 | J19: 2031 | K19: Итого 2027–2031 | L19: Как считается
A20: Входные данные (ссылки на «Допущения», «План», «Рынок»)
A21: 1 | B21: Год договора с ВТБ | C21: год | D21: =Допущения!$E$49 -> 2027
A22: 2 | B22: Клиенты-бизнесы ВТБ | C22: млн | D22: =Допущения!$E$7 -> 1.8
A23: 3 | B23: Подписка уровня 1: постоянная часть | C23: млн ₽ в год | D23: =Допущения!$E$42 -> 6
A24: 4 | B24: Плата за активного клиента-бизнес | C24: ₽ в год | D24: =Допущения!$E$43 -> 5
A25: 5 | B25: Подписка уровня 2: постоянная часть | C25: млн ₽ в год | D25: =Допущения!$E$44 -> 1.5
A26: 6 | B26: Внедрение, уровень 1 | C26: млн ₽ | D26: =Допущения!$E$45 -> 8
A27: 7 | B27: Внедрение, уровень 2 | C27: млн ₽ | D27: =Допущения!$E$46 -> 2
A28: 8 | B28: Индексация цен | C28: доля в год | D28: =Допущения!$E$47 -> 0.05
A29: 9 | B29: Рост подписки за счёт новых операций | C29: доля в год | D29: =Допущения!$E$48 -> 0.15
A30: 10 | B30: Рост окладов | C30: доля в год | D30: =Допущения!$E$51 -> 0.07
A31: 11 | B31: Взносы в пределах базы | C31: доля | D31: =Допущения!$E$52 -> 0.15
A32: 12 | B32: Взносы сверх базы | C32: доля | D32: =Допущения!$E$53 -> 0.076
A33: 13 | B33: Взнос на травматизм | C33: доля | D33: =Допущения!$E$54 -> 0.002
A34: 14 | B34: Предельная база взносов 2026 | C34: млн ₽ в год | D34: =Допущения!$E$55 -> 2.979
A35: 15 | B35: Рост базы | C35: доля в год | D35: =Допущения!$E$56 -> 0.08
A36: 16 | B36: Анализ уязвимостей по ОУД4 — первый | C36: млн ₽ | D36: =Допущения!$E$58 -> 2.5
A37: 17 | B37: Повторная оценка релизов | C37: млн ₽ в год | D37: =Допущения!$E$59 -> 1
A38: 18 | B38: Внешняя юридическая экспертиза правил | C38: млн ₽ в год | D38: =Допущения!$E$60 -> 0.6
A39: 19 | B39: Инфраструктура на сотрудника | C39: млн ₽ в год | D39: =Допущения!$E$61 -> 0.15
A40: 20 | B40: Продажи: постоянная часть | C40: млн ₽ в год | D40: =Допущения!$E$62 -> 1
A41: 21 | B41: Продажи: на договор | C41: млн ₽ | D41: =Допущения!$E$63 -> 0.4
A42: 22 | B42: Административные: постоянная часть | C42: млн ₽ в год | D42: =Допущения!$E$64 -> 1.2
A43: 23 | B43: Административные: на сотрудника | C43: млн ₽ в год | D43: =Допущения!$E$65 -> 0.1
...

Sheet Проверки
A1: Проверки
A2: Целостность — должна быть «ОК» всегда; допущения — предупреждение, если цена или доля рынка выходят за рамки
A4: № | B4: Проверка | C4: Сценарий | D4: Ожидается | E4: Факт | F4: Статус | G4: Пояснение
A5: Целостность
A6: 1 | B6: Ставки совпадают с презентацией (C-15) | C6: Консервативный | D6: 33 | E6: ='Эффект для банка'!$D$36 -> 33 | F6: =IF(E6=D6,"ОК","ОШИБКА") -> ОК | G6: эталон — реестр утверждений
A7: 2 | B7: Ущерб совпадает с презентацией (C-16) | C7: Консервативный | D7: 34 | E7: ='Эффект для банка'!$D$44 -> 34 | F7: =IF(E7=D7,"ОК","ОШИБКА") -> ОК | G7: эталон — реестр утверждений
A8: 3 | B8: Ставки совпадают с презентацией (C-15) | C8: Базовый | D8: 75 | E8: ='Эффект для банка'!$E$36 -> 75 | F8: =IF(E8=D8,"ОК","ОШИБКА") -> ОК | G8: эталон — реестр утверждений
A9: 4 | B9: Ущерб совпадает с презентацией (C-16) | C9: Базовый | D9: 115 | E9: ='Эффект для банка'!$E$44 -> 115 | F9: =IF(E9=D9,"ОК","ОШИБКА") -> ОК | G9: эталон — реестр утверждений
A10: 5 | B10: Ставки совпадают с презентацией (C-15) | C10: Оптимистичный | D10: 167 | E10: ='Эффект для банка'!$F$36 -> 167 | F10: =IF(E10=D10,"ОК","ОШИБКА") -> ОК | G10: эталон — реестр утверждений
A11: 6 | B11: Ущерб совпадает с презентацией (C-16) | C11: Оптимистичный | D11: 229 | E11: ='Эффект для банка'!$F$44 -> 229 | F11: =IF(E11=D11,"ОК","ОШИБКА") -> ОК | G11: эталон — реестр утверждений
A12: 7 | B12: Выручка = подписка + внедрение | C12: Консервативный | D12: =Консервативный!K73+Консервативный!K72 -> 37.247677 | E12: =Консервативный!K74 -> 37.247677 | F12: =IF(ABS(E12-D12)<0.000001,"ОК","ОШИБКА") -> ОК | G12: итоги 2027–2031
A13: 8 | B13: Подписка = ВТБ + уровень 1 + уровень 2 | C13: Консервативный | D13: =Консервативный!K69+Консервативный!K70+Консервативный!K71 -> 25.943193 | E13: =Консервативный!K73 -> 25.943193 | F13: =IF(ABS(E13-D13)<0.000001,"ОК","ОШИБКА") -> ОК
A14: 9 | B14: Накопленный поток = сумма потоков | C14: Консервативный | D14: =Консервативный!K116 -> -65.103095 | E14: =Консервативный!J117 -> -65.103095 | F14: =IF(ABS(E14-D14)<0.000001,"ОК","ОШИБКА") -> ОК
A15: 10 | B15: Чистая прибыль = EBITDA − налог | C15: Консервативный | D15: =Консервативный!K105-Консервативный!K110 -> -61.175255 | E15: =Консервативный!K112 -> -61.175255 | F15: =IF(ABS(E15-D15)<0.000001,"ОК","ОШИБКА") -> ОК
A16: 11 | B16: Численность и договоры не отрицательные | C16: Консервативный | D16: 0 | E16: =MIN(Консервативный!E77:J77,Консервативный!F66:J66) -> 0 | F16: =IF(E16>=D16,"ОК","ОШИБКА") -> ОК
A17: 12 | B17: Банков с договором не больше, чем в SAM | C17: Консервативный | D17: =Рынок!$D$7+Рынок!$D$8 -> 60 | E17: =Консервативный!J66 -> 4 | F17: =IF(E17<=D17,"ОК","ОШИБКА") -> ОК
A18: 13 | B18: Выручка = подписка + внедрение | C18: Базовый | D18: =Базовый!K73+Базовый!K72 -> 171.04852 | E18: =Базовый!K74 -> 171.04852 | F18: =IF(ABS(E18-D18)<0.000001,"ОК","ОШИБКА") -> ОК | G18: итоги 2027–2031
A19: 14 | B19: Подписка = ВТБ + уровень 1 + уровень 2 | C19: Базовый | D19: =Базовый!K69+Базовый!K70+Базовый!K71 -> 126.07093 | E19: =Базовый!K73 -> 126.07093 | F19: =IF(ABS(E19-D19)<0.000001,"ОК","ОШИБКА") -> ОК
A20: 15 | B20: Накопленный поток = сумма потоков | C20: Базовый | D20: =Базовый!K116 -> -12.567507 | E20: =Базовый!J117 -> -12.567507 | F20: =IF(ABS(E20-D20)<0.000001,"ОК","ОШИБКА") -> ОК
A21: 16 | B21: Чистая прибыль = EBITDA − налог | C21: Базовый | D21: =Базовый!K105-Базовый!K110 -> 4.1446186 | E21: =Базовый!K112 -> 4.1446186 | F21: =IF(ABS(E21-D21)<0.000001,"ОК","ОШИБКА") -> ОК
A22: 17 | B22: Численность и договоры не отрицательные | C22: Базовый | D22: 0 | E22: =MIN(Базовый!E77:J77,Базовый!F66:J66) -> 1 | F22: =IF(E22>=D22,"ОК","ОШИБКА") -> ОК
A23: 18 | B23: Банков с договором не больше, чем в SAM | C23: Базовый | D23: =Рынок!$E$7+Рынок!$E$8 -> 60 | E23: =Базовый!J66 -> 11 | F23: =IF(E23<=D23,"ОК","ОШИБКА") -> ОК
A24: 19 | B24: Выручка = подписка + внедрение | C24: Оптимистичный | D24: =Оптимистичный!K73+Оптимистичный!K72 -> 322.68477 | E24: =Оптимистичный!K74 -> 322.68477 | F24: =IF(ABS(E24-D24)<0.000001,"ОК","ОШИБКА") -> ОК | G24: итоги 2027–2031
A25: 20 | B25: Подписка = ВТБ + уровень 1 + уровень 2 | C25: Оптимистичный | D25: =Оптимистичный!K69+Оптимистичный!K70+Оптимистичный!K71 -> 235.49572 | E25: =Оптимистичный!K73 -> 235.49572 | F25: =IF(ABS(E25-D25)<0.000001,"ОК","ОШИБКА") -> ОК
A26: 21 | B26: Накопленный поток = сумма потоков | C26: Оптимистичный | D26: =Оптимистичный!K116 -> 26.056892 | E26: =Оптимистичный!J117 -> 26.056892 | F26: =IF(ABS(E26-D26)<0.000001,"ОК","ОШИБКА") -> ОК
A27: 22 | B27: Чистая прибыль = EBITDA − налог | C27: Оптимистичный | D27: =Оптимистичный!K105-Оптимистичный!K110 -> 49.374435 | E27: =Оптимистичный!K112 -> 49.374435 | F27: =IF(ABS(E27-D27)<0.000001,"ОК","ОШИБКА") -> ОК
A28: 23 | B28: Численность и договоры не отрицательные | C28: Оптимистичный | D28: 0 | E28: =MIN(Оптимистичный!E77:J77,Оптимистичный!F66:J66) -> 1 | F28: =IF(E28>=D28,"ОК","ОШИБКА") -> ОК
A29: 24 | B29: Банков с договором не больше, чем в SAM | C29: Оптимистичный | D29: =Рынок!$F$7+Рынок!$F$8 -> 60 | E29: =Оптимистичный!J66 -> 18 | F29: =IF(E29<=D29,"ОК","ОШИБКА") -> ОК
A30: 25 | B30: Доли уровней в сумме 100 % | C30: Консервативный | D30: 1 | E30: =Рынок!$D$10+Рынок!$D$11+Рынок!$D$29/Рынок!$D$26 -> 1 | F30: =IF(ABS(E30-D30)<0.000001,"ОК","ОШИБКА") -> ОК
A31: 26 | B31: Банков уровня 3 не меньше нуля | C31: Консервативный | D31: 0 | E31: =Рынок!$D$25 -> 241 | F31: =IF(E31>=D31,"ОК","ОШИБКА") -> ОК
A32: 27 | B32: Доли уровней в сумме 100 % | C32: Базовый | D32: 1 | E32: =Рынок!$E$10+Рынок!$E$11+Рынок!$E$29/Рынок!$E$26 -> 1 | F32: =IF(ABS(E32-D32)<0.000001,"ОК","ОШИБКА") -> ОК
A33: 28 | B33: Банков уровня 3 не меньше нуля | C33: Базовый | D33: 0 | E33: =Рынок!$E$25 -> 241 | F33: =IF(E33>=D33,"ОК","ОШИБКА") -> ОК
A34: 29 | B34: Доли уровней в сумме 100 % | C34: Оптимистичный | D34: 1 | E34: =Рынок!$F$10+Рынок!$F$11+Рынок!$F$29/Рынок!$F$26 -> 1 | F34: =IF(ABS(E34-D34)<0.000001,"ОК","ОШИБКА") -> ОК
A35: 30 | B35: Банков уровня 3 не меньше нуля | C35: Оптимистичный | D35: 0 | E35: =Рынок!$F$25 -> 241 | F35: =IF(E35>=D35,"ОК","ОШИБКА") -> ОК
A36: 31 | B36: Блок чувствительности без изменений = лист «Базовый» | C36: Базовый | D36: =Базовый!$D$136 -> -0.14959473 | E36: =Чувствительность!$D$151 -> -0.14959473 | F36: =IF(ABS(E36-D36)<0.000001,"ОК","ОШИБКА") -> ОК | G36: блоки чувствительности считаются той же формулой
A37: Допущения о цене и рынке
A38: 32 | B38: Подписка не больше 15 % прямого эффекта банка (ёмкость) | C38: Консервативный | D38: 0.15 | E38: ='Эффект для банка'!$D$67 -> 0.11669107 | F38: =IF(E38<=D38,"ОК","ВНИМАНИЕ") -> ОК | G38: клиент оставляет себе не меньше 85 % эффекта
A39: 33 | B39: Купить дешевле, чем сделать самим | C39: Консервативный | D39: 1 | E39: ='Эффект для банка'!$D$71 -> 0.4640146 | F39: =IF(E39<D39,"ОК","ВНИМАНИЕ") -> ОК | G39: затраты в год за горизонт сравнения
A40: 34 | B40: SOM не больше 40 % SAM при полном охвате | C40: Консервативный | D40: 0.4 | E40: =Рынок!$D$45 -> 0.096624629 | F40: =IF(E40<=D40,"ОК","ВНИМАНИЕ") -> ОК | G40: доля сегмента за 5 лет
A41: 35 | B41: Подписка не больше 15 % прямого эффекта банка (ёмкость) | C41: Базовый | D41: 0.15 | E41: ='Эффект для банка'!$E$67 -> 0.091076672 | F41: =IF(E41<=D41,"ОК","ВНИМАНИЕ") -> ОК | G41: клиент оставляет себе не меньше 85 % эффекта
...

Sheet Источники
A1: Источники
A2: Строки M-xx и C-xx — в CLAIMS_REGISTRY.md репозитория; там же граница каждого утверждения
A4: Код | B4: Что подтверждает | C4: Источник | D4: Дата | E4: Статус | F4: Ссылка
A5: S01 | B5: Числа о продукте: правила, автотесты, корпус, задержка | C5: evidence.json, сборка 27.10.2026; команды — в CLAIMS_REGISTRY.md (C-01…C-17) | D5: 27.10.2026 | E5: репозиторий | F5: https://github.com/KonkovDV/Mandat/blob/main/evidence.json
A6: S02 | B6: Сценарии эффекта для ВТБ (ставки, ущерб) | C6: src/mandat/data/effect_scenarios.json; python scripts/effect_model.py --scenarios (C-15, C-16) | D6: 27.10.2026 | E6: репозиторий | F6: https://github.com/KonkovDV/Mandat/blob/main/docs/ECONOMICS.md
A7: S03 | B7: Операции без согласия у юрлиц, I кв. 2026: 818 операций, 573 млн ₽, возмещено 15,9 % по счетам | C7: Банк России, обзор отчётности об инцидентах ИБ при переводе денежных средств (M-07) | D7: 14.05.2026 | E7: первичный | F7: https://cbr.ru
A8: S04 | B8: II кв. 2026: у юрлиц похищено свыше 830 млн ₽, доля юрлиц в потерях 11,3 % | C8: Банк России, обзор за II кв. 2026, в пересказе Интерфакса и Smart-Lab (M-15) | D8: 04.08.2026 | E8: вторичный | F8: https://cbr.ru
A9: S05 | B9: ВТБ обслуживает около 1,8 млн предприятий и предпринимателей | C9: Пресс-релиз ВТБ к МСФО за I полугодие 2026 в пересказе altapress.ru и kp.ru (M-09) | D9: 07.2026 | E9: вторичный | F9: https://altapress.ru
A10: S06 | B10: В реестре ФНС более 5 млн МЧД | C10: ФНС, nalog.gov.ru (M-08) | D10: 27.07.2026 | E10: первичный | F10: https://www.nalog.gov.ru
A11: S07 | B11: Около 1,6 млн МЧД в реестре ФНС | C11: emchd.ru (M-10) | D11: 28.10.2024 | E11: вторичный | F11: https://emchd.ru
A12: S08 | B12: Реестр МСП на 10.07.2026: 6 612 445 субъектов, из них 2 022 689 юрлиц и 4 589 756 ИП | C12: ФНС, ежегодное обновление реестра, в пересказе «ОПОРЫ РОССИИ» и v2b.ru (M-20) | D12: 13.07.2026 | E12: вторичный | F12: https://www.v2b.ru/2026/07/13/reestr-msp-obnovilsya-kolichestvo-predprinimateley-dostiglo-6-6-mln/
A13: S09 | B13: Перечень системно значимых банков: 12 банков, около 80 % активов | C13: The Moscow Times, vbr.ru (M-21) | D13: 07.10.2026 | E13: вторичный | F13: https://www.vbr.ru/novosti/banki/2026/10/08/bank-rossii-ytverdil-perecen-sistemno-znacimih-bankov/
A14: S10 | B14: 301 банк на 01.07.2026 | C14: brobank.ru по данным Банка России (M-22) | D14: 07.2026 | E14: вторичный | F14: https://brobank.ru/skolko-bankov-na-segodnya/
A15: S11 | B15: Ключевая ставка 14 % | C15: Решение Банка России 23.10.2026 в пересказе СМИ (M-23) | D15: 23.10.2026 | E15: вторичный | F15: https://bankiros.ru
... A34: S30 | B34: Конкуренты и ниша: проверено и не проверено | C34: docs/COMPETITORS.md, проверено 13.10.2026 | D34: 13.10.2026 | E34: репозиторий | F34: https://github.com/KonkovDV/Mandat/blob/main/docs/COMPETITORS.md
